Workbook

Sheet Foglio1
A1: Store_ID | B1: Store_Name | C1: Area/Paese | D1: Formato | E1: Posizione_Geografica | F1: Mq_Espositivi | G1: Mq_Stock | H1: Mq_Totali
A2: T76__ | B2: VIENNA | C2: AUSTRIA | D2: Turistico | E2: AUSTRIA | F2: 300 | G2: 70 | H2: 370
A3: T108_ | B3: GAND | C3: BELGIO | D3: Turistico | E3: BELGIO | F3: 241 | G3: 106 | H3: 347
A4: T129_ | B4: BRUGES | C4: BELGIO | D4: Turistico | E4: BELGIO | F4: 167 | G4: 33 | H4: 199
A5: T44__ | B5: BRUXELLES | C5: BELGIO | D5: Ibrido | E5: BELGIO | F5: 250 | G5: 106 | H5: 356
A6: T46__ | B6: ANTWERPEN | C6: BELGIO | D6: Ibrido | E6: BELGIO | F6: 120 | G6: 50 | H6: 170
A7: AGN01 | B7: SHANGAI | C7: CINA | D7: Turistico | E7: CINA | F7: 272 | G7: 21 | H7: 292
A8: AGN02 | B8: ONLINE | C8: CINA | D8: Ibrido | E8: CINA | H8: 0
A9: AGN03 | B9: CHENGDU | C9: CINA | D9: - | E9: CINA | F9: - | G9: - | H9: 0
A10: AGN05 | B10: CHENGDU | C10: CINA | D10: - | E10: CINA | F10: 93 | G10: 7 | H10: 100
A11: AGN06 | B11: RED | C11: CINA | D11: Ibrido | E11: CINA | H11: 0
A12: AGN07 | B12: GUANGZHOU | C12: CINA | D12: Di quartiere | E12: CINA | F12: 227 | G12: 60 | H12: 287
A13: AGN08 | B13: SHENZEN | C13: CINA | D13: - | E13: CINA | F13: 116 | G13: 4 | H13: 120
A14: AGNOU | B14: OUTLET | C14: CINA | D14: - | E14: CINA | H14: 0
A15: KR01_ | B15: SEOUL | C15: COREA | D15: Ibrido | E15: COREA | F15: 213 | G15: 10 | H15: 223
A16: KREC_ | B16: ONLINE | C16: COREA | D16: - | E16: COREA | F16: - | G16: - | H16: 0
A17: KR02_ | B17: SEOUL | C17: COREA | D17: - | E17: COREA | H17: 0
A18: T100_ | B18: NIZZA | C18: FRANCIA | D18: Turistico | E18: FRANCIA | F18: 190 | G18: 50 | H18: 240
A19: T107_ | B19: AIX EN PROVENCE | C19: FRANCIA | D19: Ibrido | E19: FRANCIA | F19: 75 | G19: 10 | H19: 85
A20: T111_ | B20: STRASBURGO | C20: FRANCIA | D20: Ibrido | E20: FRANCIA | F20: 151 | G20: 60 | H20: 211
A21: T112_ | B21: MARSIGLIA | C21: FRANCIA | D21: Ibrido | E21: FRANCIA | F21: 153 | G21: 29 | H21: 182
A22: T115_ | B22: TOLOSA | C22: FRANCIA | D22: Di quartiere | E22: FRANCIA | F22: 97 | G22: 80 | H22: 177
A23: T54__ | B23: PARIS | C23: FRANCIA | D23: Di quartiere | E23: FRANCIA | F23: 160 | G23: 30 | H23: 190
A24: T70LI | B24: LYON | C24: FRANCIA | D24: Di quartiere | E24: FRANCIA | F24: 120 | G24: 100 | H24: 220
A25: T75__ | B25: PARIS | C25: FRANCIA | D25: Di quartiere | E25: FRANCIA | F25: 110 | G25: 40 | H25: 150
A26: T81__ | B26: PARIS | C26: FRANCIA | D26: Ibrido | E26: FRANCIA | F26: 90 | G26: 15 | H26: 105
A27: T90__ | B27: PARIS | C27: FRANCIA | D27: Turistico | E27: FRANCIA | F27: 160 | G27: 50 | H27: 210
A28: T95__ | B28: LILLE | C28: FRANCIA | D28: Di quartiere | E28: FRANCIA | F28: 130 | G28: 25 | H28: 155
A29: T99__ | B29: BORDEAUX | C29: FRANCIA | D29: Di quartiere | E29: FRANCIA | F29: 190 | G29: 70 | H29: 260
A30: T133_ | B30: NANTES | C30: FRANCIA | D30: - | E30: FRANCIA | F30: - | G30: - | H30: 0
A31: T103_ | B31: STUTTGART | C31: GERMANIA | D31: Ibrido | E31: GERMANIA | F31: 323 | G31: 64 | H31: 387
A32: T117_ | B32: FRANKFURT | C32: GERMANIA | D32: Turistico | E32: GERMANIA | F32: 160 | G32: 80 | H32: 240
A33: T120_ | B33: COLONIA | C33: GERMANIA | D33: Ibrido | E33: GERMANIA | F33: 120 | G33: 100 | H33: 220
A34: T43__ | B34: BERLIN | C34: GERMANIA | D34: Di quartiere | E34: GERMANIA | F34: 275 | G34: 80 | H34: 355
A35: T52__ | B35: MUNCHEN | C35: GERMANIA | D35: Turistico | E35: GERMANIA | F35: 190 | G35: 65 | H35: 255
A36: T58DU | B36: DUSSELDORF | C36: GERMANIA | D36: Ibrido | E36: GERMANIA | F36: 182 | G36: 86 | H36: 268
A37: T64NU | B37: NURNBERG | C37: GERMANIA | D37: Ibrido | E37: GERMANIA | F37: 100 | G37: 25 | H37: 125
A38: T68HA | B38: HAMBURG | C38: GERMANIA | D38: Ibrido | E38: GERMANIA | F38: 255 | G38: 190 | H38: 445
A39: T83__ | B39: BERLIN | C39: GERMANIA | D39: Turistico | E39: GERMANIA | F39: 185 | G39: 60 | H39: 245
A40: T131_ | B40: BERLIN | C40: GERMANIA | D40: Turistico | E40: GERMANIA | F40: 158 | G40: 64 | H40: 222
...

Sheet Foglio2
A1: PDV | B1: COUNTRY | C1: CITTà | D1: mq area vendita | E1: mq area magazzino storage | F1: Filtro
A2: T76__ | B2: AUSTRIA | C2: Vienna | D2: 300 | E2: 70 | F2: =IF(COUNTIF(Foglio1!$A$2:$A$125, A2)=0, "Mancante", "Presente") -> Presente
A3: T108_ | B3: BELGIO | C3: Gand | D3: 241 | E3: 106 | F3: =IF(COUNTIF(Foglio1!$A$2:$A$125, A3)=0, "Mancante", "Presente") -> Presente
A4: T129_ | B4: BELGIO | C4: BRUGES | D4: 166.5 | E4: 32.6 | F4: =IF(COUNTIF(Foglio1!$A$2:$A$125, A4)=0, "Mancante", "Presente") -> Presente
A5: T44__ | B5: BELGIO | C5: Bruxelles | D5: 250 | E5: 106 | F5: =IF(COUNTIF(Foglio1!$A$2:$A$125, A5)=0, "Mancante", "Presente") -> Presente
A6: T46__ | B6: BELGIO | C6: Anversa | D6: 120 | E6: 50 | F6: =IF(COUNTIF(Foglio1!$A$2:$A$125, A6)=0, "Mancante", "Presente") -> Presente
A7: AGN02 | B7: CHINA | C7: E-commerce | F7: =IF(COUNTIF(Foglio1!$A$2:$A$125, A7)=0, "Mancante", "Presente") -> Presente
A8: AGN04 (non esiste) | B8: CHINA | C8: PECHINO | F8: =IF(COUNTIF(Foglio1!$A$2:$A$125, A8)=0, "Mancante", "Presente") -> Mancante
A9: AGN05 | B9: CHINA | C9: CHENGDU | D9: 92.5 | E9: 7 | F9: =IF(COUNTIF(Foglio1!$A$2:$A$125, A9)=0, "Mancante", "Presente") -> Presente
A10: AGN06 | B10: CHINA | F10: =IF(COUNTIF(Foglio1!$A$2:$A$125, A10)=0, "Mancante", "Presente") -> Presente
A11: AGN99 | B11: CHINA | C11: SHANGAI | F11: =IF(COUNTIF(Foglio1!$A$2:$A$125, A11)=0, "Mancante", "Presente") -> Mancante
A12: AGN01 | B12: CINA | C12: Shangai | D12: 271.5 | E12: 20.5 | F12: =IF(COUNTIF(Foglio1!$A$2:$A$125, A12)=0, "Mancante", "Presente") -> Presente
A13: AGN03 (chiuso) | B13: CINA | C13: Chengdu | D13: 187 | E13: 204 | F13: =IF(COUNTIF(Foglio1!$A$2:$A$125, A13)=0, "Mancante", "Presente") -> Mancante
A14: AGN07 | B14: CINA | C14: GUANGZHOU | D14: 227 | E14: 60 | F14: =IF(COUNTIF(Foglio1!$A$2:$A$125, A14)=0, "Mancante", "Presente") -> Presente
A15: KR01_ | B15: COREA | C15: SEOUL | D15: 213 | E15: 10 | F15: =IF(COUNTIF(Foglio1!$A$2:$A$125, A15)=0, "Mancante", "Presente") -> Presente
A16: TIM01 | B16: EMIRATI ARABI | C16: DUBAI | D16: 85 | E16: 15 | F16: =IF(COUNTIF(Foglio1!$A$2:$A$125, A16)=0, "Mancante", "Presente") -> Mancante
A17: TIM02 | B17: EMIRATI ARABI | C17: DUBAI | D17: 144 | E17: 36 | F17: =IF(COUNTIF(Foglio1!$A$2:$A$125, A17)=0, "Mancante", "Presente") -> Mancante
A18: T100_ | B18: FRANCIA | C18: Nizza | D18: 190 | E18: 50 | F18: =IF(COUNTIF(Foglio1!$A$2:$A$125, A18)=0, "Mancante", "Presente") -> Presente
A19: T107_ | B19: FRANCIA | C19: Aix en Provence | D19: 75 | E19: 10 | F19: =IF(COUNTIF(Foglio1!$A$2:$A$125, A19)=0, "Mancante", "Presente") -> Presente
A20: T111_ | B20: FRANCIA | C20: Strasburgo | D20: 151 | E20: 60 | F20: =IF(COUNTIF(Foglio1!$A$2:$A$125, A20)=0, "Mancante", "Presente") -> Presente
A21: T112_ | B21: FRANCIA | C21: Marsiglia | D21: 153 | E21: 29 | F21: =IF(COUNTIF(Foglio1!$A$2:$A$125, A21)=0, "Mancante", "Presente") -> Presente
A22: T115_ | B22: FRANCIA | C22: Tolosa | D22: 97 | E22: 80 | F22: =IF(COUNTIF(Foglio1!$A$2:$A$125, A22)=0, "Mancante", "Presente") -> Presente
A23: T54__ | B23: FRANCIA | C23: Paris | D23: 160 | E23: 30 | F23: =IF(COUNTIF(Foglio1!$A$2:$A$125, A23)=0, "Mancante", "Presente") -> Presente
... A95: T49__ | B95: OLANDA | C95: Amsterdam | D95: 104 | E95: 80 | F95: =IF(COUNTIF(Foglio1!$A$2:$A$125, A95)=0, "Mancante", "Presente") -> Presente
A96: T72UT | B96: OLANDA | C96: Utrecht | D96: 90 | F96: =IF(COUNTIF(Foglio1!$A$2:$A$125, A96)=0, "Mancante", "Presente") -> Presente
A97: T96__ | B97: OLANDA | C97: Aia | D97: 97 | E97: 60 | F97: =IF(COUNTIF(Foglio1!$A$2:$A$125, A97)=0, "Mancante", "Presente") -> Presente
A98: SIG01 | B98: SINGAPORE | C98: SINGAPORE | D98: 100 | E98: 24 | F98: =IF(COUNTIF(Foglio1!$A$2:$A$125, A98)=0, "Mancante", "Presente") -> Mancante
A99: T102_ | B99: SPAGNA | C99: Zaragozza | D99: 114.4 | E99: 15.4 | F99: =IF(COUNTIF(Foglio1!$A$2:$A$125, A99)=0, "Mancante", "Presente") -> Presente
A100: T106_ | B100: SPAGNA | C100: Madrid 3 | D100: 93.64 | E100: 14.38 | F100: =IF(COUNTIF(Foglio1!$A$2:$A$125, A100)=0, "Mancante", "Presente") -> Presente
A101: T48__ | B101: SPAGNA | C101: Barcellona | D101: 191 | E101: 95 | F101: =IF(COUNTIF(Foglio1!$A$2:$A$125, A101)=0, "Mancante", "Presente") -> Presente
A102: T57IB | B102: SPAGNA | C102: Ibiza | D102: 57 | E102: 6 | F102: =IF(COUNTIF(Foglio1!$A$2:$A$125, A102)=0, "Mancante", "Presente") -> Presente
A103: T61MD | B103: SPAGNA | C103: Madrid2 | D103: 99 | E103: 15 | F103: =IF(COUNTIF(Foglio1!$A$2:$A$125, A103)=0, "Mancante", "Presente") -> Presente
A104: T62BB | B104: SPAGNA | C104: Bilbao | D104: 150 | E104: 34 | F104: =IF(COUNTIF(Foglio1!$A$2:$A$125, A104)=0, "Mancante", "Presente") -> Presente
A105: T67B2 | B105: SPAGNA | C105: Barcellon | D105: 86 | E105: 8 | F105: =IF(COUNTIF(Foglio1!$A$2:$A$125, A105)=0, "Mancante", "Presente") -> Presente
A106: T69VA | B106: SPAGNA | C106: Valencia | D106: 168 | E106: 40 | F106: =IF(COUNTIF(Foglio1!$A$2:$A$125, A106)=0, "Mancante", "Presente") -> Presente
A107: T71LC | B107: SPAGNA | C107: La Coruna | D107: 99 | E107: 21 | F107: =IF(COUNTIF(Foglio1!$A$2:$A$125, A107)=0, "Mancante", "Presente") -> Presente
A108: T77__ | B108: SPAGNA | C108: Siviglia | D108: 120 | E108: 90 | F108: =IF(COUNTIF(Foglio1!$A$2:$A$125, A108)=0, "Mancante", "Presente") -> Presente
... A117: T119_ | B117: SVIZZERA | C117: Losanna | D117: 183 | E117: 104 | F117: =IF(COUNTIF(Foglio1!$A$2:$A$125, A117)=0, "Mancante", "Presente") -> Presente
A118: T126_ | B118: SVIZZERA | C118: BASILEA | D118: 110mq | E118: 70 | F118: =IF(COUNTIF(Foglio1!$A$2:$A$125, A118)=0, "Mancante", "Presente") -> Presente
A119: T65ZU | B119: SVIZZERA | C119: Zurigo | D119: 170 | E119: 40 | F119: =IF(COUNTIF(Foglio1!$A$2:$A$125, A119)=0, "Mancante", "Presente") -> Presente
...
